Workbook

Sheet Summary
A1: Crude Oil Market Risk Report
A2: Hypothetical long WTI / short Brent position. All figures recalculate from the Inputs sheet.
A4: Position snapshot
A5: As-of date | B5: =VaR!B8 -> 46294
A6: WTI price ($/bbl) | B6: =VaR!B11 -> 96.16
A7: Brent price ($/bbl) | B7: =VaR!B12 -> 113.96
A8: WTI position (bbl) | B8: =Inputs!$B$5 -> 100000
A9: Brent position (bbl) | B9: =Inputs!$B$6 -> -50000
A10: MTM value ($) | B10: =VaR!B15 -> 3918000
A11: Last-day P&L ($) | B11: =INDEX(Prices_MTM!I:I,VaR!B5) -> -20500
A12: P&L, trailing 250 days ($) | B12: =INDEX(Prices_MTM!J:J,VaR!B5)-INDEX(Prices_MTM!J:J,VaR!B5-250) -> 962500
A13: VaR window | B13: =TEXT(VaR!B7,"yyyy-mm-dd")&" to "&TEXT(VaR!B8,"yyyy-mm-dd") -> 2024-09-13 to 2026-09-29
A15: 1-day VaR and Expected Shortfall ($ loss)
A16: Method | B16: ="VaR "&TEXT(Inputs!B8,"0%") -> VaR 95% | C16: ="ES "&TEXT(Inputs!B8,"0%") -> ES 95% | D16: ="VaR "&TEXT(Inputs!B9,"0%") -> VaR 99% | E16: ="ES "&TEXT(Inputs!B9,"0%") -> ES 99%
A17: =VaR!A29 -> Historical simulation | B17: =VaR!B29 -> 195600 | C17: =VaR!C29 -> 418200 | D17: =VaR!D29 -> 474615 | E17: =VaR!E29 -> 802800
A18: =VaR!A30 -> Parametric (variance-covariance) | B18: =VaR!B30 -> 265690.41 | C18: =VaR!C30 -> 333186.5 | D18: =VaR!D30 -> 375771.02 | E18: =VaR!E30 -> 430507.53
A19: =VaR!A31 -> Monte Carlo (normal) | B19: =VaR!B31 -> 263628.74 | C19: =VaR!C31 -> 328458.96 | D19: =VaR!D31 -> 365438.76 | E19: =VaR!E31 -> 417356.35
A20: =VaR!A32 -> Monte Carlo (Student-t) | B20: =VaR!B32 -> 249044.19 | C20: =VaR!C32 -> 380152.16 | D20: =VaR!D32 -> 456786.07 | E20: =VaR!E32 -> 618665.98
A23: Backtest (rolling 250-day VaR vs actual P&L)
A24: Test | B24: Hist CL1 | C24: Param CL1 | D24: Hist CL2 | E24: Param CL2
A25: =Backtest!A6 -> Days tested | B25: =Backtest!B6 -> 5784 | C25: =Backtest!C6 -> 5784 | D25: =Backtest!D6 -> 5784 | E25: =Backtest!E6 -> 5784
A26: =Backtest!A7 -> Expected exceptions | B26: =Backtest!B7 -> 289.2 | C26: =Backtest!C7 -> 289.2 | D26: =Backtest!D7 -> 57.84 | E26: =Backtest!E7 -> 57.84
A27: =Backtest!A8 -> Actual exceptions | B27: =Backtest!B8 -> 331 | C27: =Backtest!C8 -> 304 | D27: =Backtest!D8 -> 97 | E27: =Backtest!E8 -> 111
A28: =Backtest!A9 -> Exception rate | B28: =Backtest!B9 -> 0.057226833 | C28: =Backtest!C9 -> 0.052558783 | D28: =Backtest!D9 -> 0.016770401 | E28: =Backtest!E9 -> 0.019190871
A29: =Backtest!A11 -> Kupiec p-value | B29: =Backtest!B11 -> 0.013604808 | C29: =Backtest!C11 -> 0.37570776 | D29: =Backtest!D11 -> 2.3907009e-06 | E29: =Backtest!E11 -> 4.4936661e-10
A30: =Backtest!A12 -> Kupiec result (5%) | B30: =Backtest!B12 -> Reject | C30: =Backtest!C12 -> Pass | D30: =Backtest!D12 -> Reject | E30: =Backtest!E12 -> Reject
A31: =Backtest!A13 -> Exceptions, last 250 days | B31: =Backtest!B13 -> 22 | C31: =Backtest!C13 -> 18 | D31: =Backtest!D13 -> 8 | E31: =Backtest!E13 -> 9
A32: =Backtest!A14 -> Basel traffic light (CL2 only) | B32: =Backtest!B14 -> n/a | C32: =Backtest!C14 -> n/a | D32: =Backtest!D14 -> Yellow | E32: =Backtest!E14 -> Yellow
A35: Stress scenarios
A36: Scenario | B36: WTI stressed | C36: Brent stressed | D36: P&L ($) | E36: x 99% VaR
A37: =Stress!A10 -> Negative WTI (20 Apr 2020, 1 day) | B37: =Stress!H10 -> 40.87 | C37: =Stress!I10 -> 111.57 | D37: =Stress!L10 -> -5409500 | E37: =Stress!M10 -> -11.397659
A38: =Stress!A11 -> COVID / OPEC+ price war (9 Mar 2020, 1 day) | B38: =Stress!H11 -> 72.57579 | C38: =Stress!I11 -> 88.294009 | D38: =Stress!L11 -> -1075121.4 | E38: =Stress!M11 -> -2.2652496
A39: =Stress!A12 -> 2022 Russia spike (24 Feb - 8 Mar 2022) | B39: =Stress!H12 -> 129.03432 | C39: =Stress!I12 -> 152.85721 | D39: =Stress!L12 -> 1342571.5 | E39: =Stress!M12 -> 2.828759
A40: =Stress!A13 -> 2022 spike reversal (9 Mar 2022, 1 day) | B40: =Stress!H13 -> 84.626089 | C40: =Stress!I13 -> 99.755645 | D40: =Stress!L13 -> -443173.39 | E40: =Stress!M13 -> -0.93375343
A41: =Stress!A14 -> 2008 GFC collapse (Jul - Dec 2008) | B41: =Stress!H14 -> 21.9505 | C41: =Stress!I14 -> 31.286552 | D41: =Stress!L14 -> -3287277.6 | E41: =Stress!M14 -> -6.9261983
A42: =Stress!A15 -> 2014-15 OPEC supply glut | B42: =Stress!H15 -> 40.904745 | C42: =Stress!I15 -> 44.897554 | D42: =Stress!L15 -> -2072403.2 | E42: =Stress!M15 -> -4.3664933
A43: =Stress!A16 -> Parallel crash -30% | B43: =Stress!H16 -> 67.312 | C43: =Stress!I16 -> 79.772 | D43: =Stress!L16 -> -1175400 | E43: =Stress!M16 -> -2.4765336
A44: =Stress!A17 -> Parallel spike +30% | B44: =Stress!H17 -> 125.008 | C44: =Stress!I17 -> 148.148 | D44: =Stress!L17 -> 1175400 | E44: =Stress!M17 -> 2.4765336
A45: =Stress!A18 -> Spread blowout: WTI -$5, Brent +$10 | B45: =Stress!H18 -> 91.16 | C45: =Stress!I18 -> 123.96 | D45: =Stress!L18 -> -1000000 | E45: =Stress!M18 -> -2.1069709
A46: =Stress!A19 -> WTI to -$40 at expiry, Brent -20% | B46: =Stress!H19 -> -40 | C46: =Stress!I19 -> 91.168 | D46: =Stress!L19 -> -12476400 | E46: =Stress!M19 -> -26.287412
...

Sheet Inputs
A1: Inputs
A2: Blue = hardcoded input. Yellow = key assumption you can change; every other sheet recalculates.
A4: Parameter | B4: Value | C4: Note
A5: Position: WTI (bbl, + = long) | B5: 100000 | C5: Hypothetical long Cushing barrels (e.g. storage inventory).
A6: Position: Brent (bbl, + = long) | B6: -50000 | C6: Short Brent as a partial hedge; leaves basis (WTI-Brent spread) risk.
A7: VaR lookback window (days) | B7: 500 | C7: Number of most recent daily price changes used for today's VaR.
A8: Confidence level 1 | B8: 0.95 | C8: 1-day VaR confidence.
A9: Confidence level 2 | B9: 0.99 | C9: 1-day VaR confidence (Basel standard).
A10: Student-t degrees of freedom (MC) | B10: 4 | C10: Fat-tailed Monte Carlo variant. Lower = fatter tails; must be > 2.
A11: Backtest window (days) | B11: 250 | C11: Fixed at 250 in the Backtest sheet formulas (non-volatile ranges for speed). Python version is configurable.
A14: Data source
A15: EIA spot prices: WTI Cushing (RWTC) and Brent Europe (RBRTE), $/bbl, daily. https://www.eia.gov/dnav/pet/pet_pri_spt_s1_d.htm
A16: Common trading dates from 2000-01-04 to 2026-09-29 (6,035 rows).
A18: Method notes
A19: 1. P&L is computed from dollar price changes (dP), not % returns: WTI settled at -$36.98 on 2020-04-20, where % and log returns break.
A20: 2. Daily P&L = WTI qty x dWTI + Brent qty x dBrent, for the position held constant through history (hypothetical P&L).
A21: 3. Historical VaR = -PERCENTILE of the last N daily P&L outcomes. Parametric = z x portfolio sigma (zero mean). Monte Carlo = 10,000 correlated draws via Cholesky of the same covariance.
A22: 4. Expected Shortfall (ES) = average loss beyond VaR, shown alongside because Basel FRTB replaced 99% VaR with 97.5% ES.

Sheet Prices_MTM
A1: Date | B1: WTI ($/bbl) | C1: Brent ($/bbl) | D1: dWTI ($) | E1: dBrent ($) | F1: MTM value ($) | G1: P&L WTI ($) | H1: P&L Brent ($) | I1: Daily P&L ($) | J1: Cumulative P&L ($)
A2: 36529 | B2: 25.56 | C2: 23.95 | F2: =Inputs!$B$5*B2+Inputs!$B$6*C2 -> 1358500 | J2: 0
A3: 36530 | B3: 24.65 | C3: 23.72 | D3: =B3-B2 -> -0.91 | E3: =C3-C2 -> -0.23 | F3: =Inputs!$B$5*B3+Inputs!$B$6*C3 -> 1279000 | G3: =Inputs!$B$5*D3 -> -91000 | H3: =Inputs!$B$6*E3 -> 11500 | I3: =G3+H3 -> -79500 | J3: =J2+I3 -> -79500
A4: 36531 | B4: 24.79 | C4: 23.55 | D4: =B4-B3 -> 0.14 | E4: =C4-C3 -> -0.17 | F4: =Inputs!$B$5*B4+Inputs!$B$6*C4 -> 1301500 | G4: =Inputs!$B$5*D4 -> 14000 | H4: =Inputs!$B$6*E4 -> 8500 | I4: =G4+H4 -> 22500 | J4: =J3+I4 -> -57000
A5: 36532 | B5: 24.79 | C5: 23.35 | D5: =B5-B4 -> 0 | E5: =C5-C4 -> -0.2 | F5: =Inputs!$B$5*B5+Inputs!$B$6*C5 -> 1311500 | G5: =Inputs!$B$5*D5 -> 0 | H5: =Inputs!$B$6*E5 -> 10000 | I5: =G5+H5 -> 10000 | J5: =J4+I5 -> -47000
A6: 36535 | B6: 24.71 | C6: 22.77 | D6: =B6-B5 -> -0.08 | E6: =C6-C5 -> -0.58 | F6: =Inputs!$B$5*B6+Inputs!$B$6*C6 -> 1332500 | G6: =Inputs!$B$5*D6 -> -8000 | H6: =Inputs!$B$6*E6 -> 29000 | I6: =G6+H6 -> 21000 | J6: =J5+I6 -> -26000
A7: 36536 | B7: 25.69 | C7: 23.93 | D7: =B7-B6 -> 0.98 | E7: =C7-C6 -> 1.16 | F7: =Inputs!$B$5*B7+Inputs!$B$6*C7 -> 1372500 | G7: =Inputs!$B$5*D7 -> 98000 | H7: =Inputs!$B$6*E7 -> -58000 | I7: =G7+H7 -> 40000 | J7: =J6+I7 -> 14000
A8: 36537 | B8: 26.3 | C8: 24.62 | D8: =B8-B7 -> 0.61 | E8: =C8-C7 -> 0.69 | F8: =Inputs!$B$5*B8+Inputs!$B$6*C8 -> 1399000 | G8: =Inputs!$B$5*D8 -> 61000 | H8: =Inputs!$B$6*E8 -> -34500 | I8: =G8+H8 -> 26500 | J8: =J7+I8 -> 40500
A9: 36543 | B9: 28.98 | C9: 26.31 | D9: =B9-B8 -> 2.68 | E9: =C9-C8 -> 1.69 | F9: =Inputs!$B$5*B9+Inputs!$B$6*C9 -> 1582500 | G9: =Inputs!$B$5*D9 -> 268000 | H9: =Inputs!$B$6*E9 -> -84500 | I9: =G9+H9 -> 183500 | J9: =J8+I9 -> 224000
A10: 36544 | B10: 29.11 | C10: 26.17 | D10: =B10-B9 -> 0.13 | E10: =C10-C9 -> -0.14 | F10: =Inputs!$B$5*B10+Inputs!$B$6*C10 -> 1602500 | G10: =Inputs!$B$5*D10 -> 13000 | H10: =Inputs!$B$6*E10 -> 7000 | I10: =G10+H10 -> 20000 | J10: =J9+I10 -> 244000
A11: 36545 | B11: 29.67 | C11: 26.26 | D11: =B11-B10 -> 0.56 | E11: =C11-C10 -> 0.09 | F11: =Inputs!$B$5*B11+Inputs!$B$6*C11 -> 1654000 | G11: =Inputs!$B$5*D11 -> 56000 | H11: =Inputs!$B$6*E11 -> -4500 | I11: =G11+H11 -> 51500 | J11: =J10+I11 -> 295500
A12: 36546 | B12: 29.71 | C12: 27.18 | D12: =B12-B11 -> 0.04 | E12: =C12-C11 -> 0.92 | F12: =Inputs!$B$5*B12+Inputs!$B$6*C12 -> 1612000 | G12: =Inputs!$B$5*D12 -> 4000 | H12: =Inputs!$B$6*E12 -> -46000 | I12: =G12+H12 -> -42000 | J12: =J11+I12 -> 253500
A13: 36550 | B13: 30.28 | C13: 27.24 | D13: =B13-B12 -> 0.57 | E13: =C13-C12 -> 0.06 | F13: =Inputs!$B$5*B13+Inputs!$B$6*C13 -> 1666000 | G13: =Inputs!$B$5*D13 -> 57000 | H13: =Inputs!$B$6*E13 -> -3000 | I13: =G13+H13 -> 54000 | J13: =J12+I13 -> 307500
A14: 36552 | B14: 27.22 | C14: 26.91 | D14: =B14-B13 -> -3.06 | E14: =C14-C13 -> -0.33 | F14: =Inputs!$B$5*B14+Inputs!$B$6*C14 -> 1376500 | G14: =Inputs!$B$5*D14 -> -306000 | H14: =Inputs!$B$6*E14 -> 16500 | I14: =G14+H14 -> -289500 | J14: =J13+I14 -> 18000
... A6036: 46294 | B6036: 96.16 | C6036: 113.96 | D6036: =B6036-B6035 -> -3.21 | E6036: =C6036-C6035 -> -6.01 | F6036: =Inputs!$B$5*B6036+Inputs!$B$6*C6036 -> 3918000 | G6036: =Inputs!$B$5*D6036 -> -321000 | H6036: =Inputs!$B$6*E6036 -> 300500 | I6036: =G6036+H6036 -> -20500 | J6036: =J6035+I6036 -> 2559500

Sheet VaR
A1: 1-Day Value at Risk
A2: Today's VaR on the last N daily price changes (N set on Inputs).
A4: Window
A5: Last data row on Prices_MTM | B5: =COUNTA(Prices_MTM!A:A) -> 6036
A6: First row of window | B6: =B5-Inputs!$B$7+1 -> 5537
A7: Window start date | B7: =INDEX(Prices_MTM!A:A,B6) -> 45548
A8: As-of date | B8: =INDEX(Prices_MTM!A:A,B5) -> 46294
A10: Position and window statistics
A11: WTI price ($/bbl) | B11: =INDEX(Prices_MTM!B:B,B5) -> 96.16
A12: Brent price ($/bbl) | B12: =INDEX(Prices_MTM!C:C,B5) -> 113.96
A13: WTI position (bbl) | B13: =Inputs!$B$5 -> 100000
A14: Brent position (bbl) | B14: =Inputs!$B$6 -> -50000
A15: MTM value ($) | B15: =INDEX(Prices_MTM!F:F,B5) -> 3918000
A16: Gross notional ($) | B16: =ABS(B13*B11)+ABS(B14*B12) -> 15314000
A17: Std dev dWTI ($/bbl/day) | B17: =STDEV(INDEX(Prices_MTM!D:D,$B$6):INDEX(Prices_MTM!D:D,$B$5)) -> 2.554978
A18: Std dev dBrent ($/bbl/day) | B18: =STDEV(INDEX(Prices_MTM!E:E,$B$6):INDEX(Prices_MTM!E:E,$B$5)) -> 2.9400824
A19: Correlation dWTI, dBrent | B19: =CORREL(INDEX(Prices_MTM!D:D,$B$6):INDEX(Prices_MTM!D:D,$B$5),INDEX(Prices_MTM!E:E,$B$6):INDEX(Prices_MTM!E:E,$B$5)) -> 0.80936094
A20: Covariance (sample) | B20: =B19*B17*B18 -> 6.0797946
A21: Portfolio sigma ($/day) | B21: =SQRT(B13^2*B17^2+B14^2*B18^2+2*B13*B14*B20) -> 161528.3
A22: Check: STDEV of window P&L | B22: =STDEV(INDEX(Prices_MTM!I:I,$B$6):INDEX(Prices_MTM!I:I,$B$5)) -> 161528.3 | C22: Must equal B21: sigma of portfolio P&L = sqrt(q'Σq)
A25: 1-day VaR and Expected Shortfall ($ loss)
A26: Method | B26: VaR @ CL1 | C26: ES @ CL1 | D26: VaR @ CL2 | E26: ES @ CL2
A27: Confidence | B27: =Inputs!$B$8 -> 0.95 | C27: =Inputs!$B$8 -> 0.95 | D27: =Inputs!$B$9 -> 0.99 | E27: =Inputs!$B$9 -> 0.99
A28: z-score | B28: =NORMSINV(B27) -> 1.6448536 | D28: =NORMSINV(D27) -> 2.3263479
A29: Historical simulation | B29: =-PERCENTILE(INDEX(Prices_MTM!I:I,$B$6):INDEX(Prices_MTM!I:I,$B$5),1-B$27) -> 195600 | C29: =-AVERAGEIF(INDEX(Prices_MTM!I:I,$B$6):INDEX(Prices_MTM!I:I,$B$5),"<="&-B29) -> 418200 | D29: =-PERCENTILE(INDEX(Prices_MTM!I:I,$B$6):INDEX(Prices_MTM!I:I,$B$5),1-D$27) -> 474615 | E29: =-AVERAGEIF(INDEX(Prices_MTM!I:I,$B$6):INDEX(Prices_MTM!I:I,$B$5),"<="&-D29) -> 802800
A30: Parametric (variance-covariance) | B30: =B$28*$B$21 -> 265690.41 | C30: =$B$21*NORMDIST(B$28,0,1,FALSE())/(1-B$27) -> 333186.5 | D30: =D$28*$B$21 -> 375771.02 | E30: =$B$21*NORMDIST(D$28,0,1,FALSE())/(1-D$27) -> 430507.53
A31: Monte Carlo (normal) | B31: =-PERCENTILE(MC_Sim!$F$9:$F$10008,1-B$27) -> 263628.74 | C31: =-AVERAGEIF(MC_Sim!$F$9:$F$10008,"<="&-B31) -> 328458.96 | D31: =-PERCENTILE(MC_Sim!$F$9:$F$10008,1-D$27) -> 365438.76 | E31: =-AVERAGEIF(MC_Sim!$F$9:$F$10008,"<="&-D31) -> 417356.35
A32: Monte Carlo (Student-t) | B32: =-PERCENTILE(MC_Sim!$G$9:$G$10008,1-B$27) -> 249044.19 | C32: =-AVERAGEIF(MC_Sim!$G$9:$G$10008,"<="&-B32) -> 380152.16 | D32: =-PERCENTILE(MC_Sim!$G$9:$G$10008,1-D$27) -> 456786.07 | E32: =-AVERAGEIF(MC_Sim!$G$9:$G$10008,"<="&-D32) -> 618665.98
A33: VaR as % of gross notional (hist, CL2) | D33: =D29/B16 -> 0.030992229
A34: Ratio hist / parametric (CL2): >1 = fat tails | D34: =D29/D30 -> 1.2630431
A37: Parametric component VaR @ CL2 (sums to total)
A38: Leg | B38: Component VaR ($) | C38: % of total
A39: WTI | B39: =B13*(B13*B17^2+B14*B20)/B21*D28 -> 502347.72 | C39: =B39/B41 -> 1.3368453
A40: Brent | B40: =B14*(B14*B18^2+B13*B20)/B21*D28 -> -126576.7 | C40: =B40/B41 -> -0.33684529
A41: Total | B41: =B39+B40 -> 375771.02 | C41: =C39+C40 -> 1
A42: A negative component means that leg is hedging (reducing) total risk.

Sheet MC_Sim
A1: Monte Carlo simulation (10,000 draws)
A2: Z1, Z2 ~ N(0,1) and W ~ chi-square(df) are seeded draws (seed 42), identical to the Python model. Replace with =NORMSINV(RAND()) to re-randomise.
A4: Cholesky of window covariance
A5: L11 | B5: =VaR!B17 -> 2.554978 | C5: L21 | D5: =VaR!B19*VaR!B18 -> 2.3795878 | E5: L22 | F5: =VaR!B18*SQRT(1-VaR!B19^2) -> 1.7267444
A6: df | B6: =Inputs!$B$10 -> 4
A8: Z1 | B8: Z2 | C8: W (chi2) | D8: sim dWTI | E8: sim dBrent | F8: P&L normal ($) | G8: P&L Student-t ($)
A9: 0.30471708 | B9: -1.0399841 | C9: 3.1857293 | D9: =$B$5*A9 -> 0.77854545 | E9: =$D$5*A9+$F$5*B9 -> -1.0706856 | F9: =Inputs!$B$5*D9+Inputs!$B$6*E9 -> 131388.83 | G9: =F9*SQRT(($B$6-2)/C9) -> 104104.38
A10: 0.7504512 | B10: 0.94056472 | C10: 2.7267596 | D10: =$B$5*A10 -> 1.9173863 | E10: =$D$5*A10+$F$5*B10 -> 3.4098793 | F10: =Inputs!$B$5*D10+Inputs!$B$6*E10 -> 21244.665 | G10: =F10*SQRT(($B$6-2)/C10) -> 18194.556
A11: -1.9510352 | B11: -1.3021795 | C11: 5.6002982 | D11: =$B$5*A11 -> -4.9848521 | E11: =$D$5*A11+$F$5*B11 -> -6.8911907 | F11: =Inputs!$B$5*D11+Inputs!$B$6*E11 -> -153925.67 | G11: =F11*SQRT(($B$6-2)/C11) -> -91985.734
A12: 0.1278404 | B12: -0.31624259 | C12: 1.1724066 | D12: =$B$5*A12 -> 0.32662942 | E12: =$D$5*A12+$F$5*B12 -> -0.24186264 | F12: =Inputs!$B$5*D12+Inputs!$B$6*E12 -> 44756.074 | G12: =F12*SQRT(($B$6-2)/C12) -> 58455.835
A13: -0.016801158 | B13: -0.85304393 | C13: 5.6801859 | D13: =$B$5*A13 -> -0.042926588 | E13: =$D$5*A13+$F$5*B13 -> -1.5129686 | F13: =Inputs!$B$5*D13+Inputs!$B$6*E13 -> 71355.772 | G13: =F13*SQRT(($B$6-2)/C13) -> 42341.168
A14: 0.87939797 | B14: 0.77779194 | C14: 3.0374721 | D14: =$B$5*A14 -> 2.2468425 | E14: =$D$5*A14+$F$5*B14 -> 3.4356525 | F14: =Inputs!$B$5*D14+Inputs!$B$6*E14 -> 52901.624 | G14: =F14*SQRT(($B$6-2)/C14) -> 42926.735
A15: 0.066030698 | B15: 1.1272412 | C15: 4.6662807 | D15: =$B$5*A15 -> 0.16870698 | E15: =$D$5*A15+$F$5*B15 -> 2.1035832 | F15: =Inputs!$B$5*D15+Inputs!$B$6*E15 -> -88308.464 | G15: =F15*SQRT(($B$6-2)/C15) -> -57813.851
A16: 0.46750934 | B16: -0.85929246 | C16: 1.2757446 | D16: =$B$5*A16 -> 1.1944761 | E16: =$D$5*A16+$F$5*B16 -> -0.37129887 | F16: =Inputs!$B$5*D16+Inputs!$B$6*E16 -> 138012.55 | G16: =F16*SQRT(($B$6-2)/C16) -> 172803.17
A17: 0.36875078 | B17: -0.9588826 | C17: 5.8392782 | D17: =$B$5*A17 -> 0.94215015 | E17: =$D$5*A17+$F$5*B17 -> -0.77827024 | F17: =Inputs!$B$5*D17+Inputs!$B$6*E17 -> 133128.53 | G17: =F17*SQRT(($B$6-2)/C17) -> 77912.393
A18: 0.8784503 | B18: -0.049925911 | C18: 7.3746218 | D18: =$B$5*A18 -> 2.2444212 | E18: =$D$5*A18+$F$5*B18 -> 2.0041404 | F18: =Inputs!$B$5*D18+Inputs!$B$6*E18 -> 124235.1 | G18: =F18*SQRT(($B$6-2)/C18) -> 64697.791
A19: -0.18486236 | B19: -0.68092954 | C19: 23.528467 | D19: =$B$5*A19 -> -0.47231928 | E19: =$D$5*A19+$F$5*B19 -> -1.6156875 | F19: =Inputs!$B$5*D19+Inputs!$B$6*E19 -> 33552.446 | G19: =F19*SQRT(($B$6-2)/C19) -> 9782.3313
A20: 1.2225413 | B20: -0.15452948 | C20: 4.4423964 | D20: =$B$5*A20 -> 3.1235663 | E20: =$D$5*A20+$F$5*B20 -> 2.6423116 | F20: =Inputs!$B$5*D20+Inputs!$B$6*E20 -> 180241.05 | G20: =F20*SQRT(($B$6-2)/C20) -> 120937.24
... A10008: 0.5310428 | B10008: 1.1749809 | C10008: 1.95841 | D10008: =$B$5*A10008 -> 1.3568027 | E10008: =$D$5*A10008+$F$5*B10008 -> 3.2925546 | F10008: =Inputs!$B$5*D10008+Inputs!$B$6*E10008 -> -28947.461 | G10008: =F10008*SQRT(($B$6-2)/C10008) -> -29253.22

Sheet Backtest
A1: VaR backtest (rolling 250-day window)
A2: Each day's VaR uses only the 250 days before it, then is compared with that day's actual P&L. Exception = loss larger than VaR. Monte Carlo backtest is in the Python version.
A4: Summary | L4: Exceptions by year (clusters in 2008, 2014, 2026)
A5: Test | B5: Hist CL1 | C5: Param CL1 | D5: Hist CL2 | E5: Param CL2 | L5: Year | M5: Days | N5: Hist CL1 | O5: Param CL1 | P5: Hist CL2 | Q5: Param CL2
A6: Days tested | B6: =COUNT($B$20:$B$5803) -> 5784 | C6: =COUNT($B$20:$B$5803) -> 5784 | D6: =COUNT($B$20:$B$5803) -> 5784 | E6: =COUNT($B$20:$B$5803) -> 5784 | L6: 2001 | M6: =SUMPRODUCT(--(TEXT($A$20:$A$5803,"yyyy")=$L6)) -> 100 | N6: =SUMPRODUCT((TEXT($A$20:$A$5803,"yyyy")=$L6)*$G$20:$G$5803) -> 4 | O6: =SUMPRODUCT((TEXT($A$20:$A$5803,"yyyy")=$L6)*$H$20:$H$5803) -> 3 | P6: =SUMPRODUCT((TEXT($A$20:$A$5803,"yyyy")=$L6)*$I$20:$I$5803) -> 1 | Q6: =SUMPRODUCT((TEXT($A$20:$A$5803,"yyyy")=$L6)*$J$20:$J$5803) -> 2
A7: Expected exceptions | B7: =B6*(1-Inputs!$B$8) -> 289.2 | C7: =C6*(1-Inputs!$B$8) -> 289.2 | D7: =D6*(1-Inputs!$B$9) -> 57.84 | E7: =E6*(1-Inputs!$B$9) -> 57.84 | L7: 2002 | M7: =SUMPRODUCT(--(TEXT($A$20:$A$5803,"yyyy")=$L7)) -> 170 | N7: =SUMPRODUCT((TEXT($A$20:$A$5803,"yyyy")=$L7)*$G$20:$G$5803) -> 4 | O7: =SUMPRODUCT((TEXT($A$20:$A$5803,"yyyy")=$L7)*$H$20:$H$5803) -> 3 | P7: =SUMPRODUCT((TEXT($A$20:$A$5803,"yyyy")=$L7)*$I$20:$I$5803) -> 0 | Q7: =SUMPRODUCT((TEXT($A$20:$A$5803,"yyyy")=$L7)*$J$20:$J$5803) -> 2
A8: Actual exceptions | B8: =SUM(G20:G5803) -> 331 | C8: =SUM(H20:H5803) -> 304 | D8: =SUM(I20:I5803) -> 97 | E8: =SUM(J20:J5803) -> 111 | L8: 2003 | M8: =SUMPRODUCT(--(TEXT($A$20:$A$5803,"yyyy")=$L8)) -> 118 | N8: =SUMPRODUCT((TEXT($A$20:$A$5803,"yyyy")=$L8)*$G$20:$G$5803) -> 11 | O8: =SUMPRODUCT((TEXT($A$20:$A$5803,"yyyy")=$L8)*$H$20:$H$5803) -> 9 | P8: =SUMPRODUCT((TEXT($A$20:$A$5803,"yyyy")=$L8)*$I$20:$I$5803) -> 4 | Q8: =SUMPRODUCT((TEXT($A$20:$A$5803,"yyyy")=$L8)*$J$20:$J$5803) -> 4
A9: Exception rate | B9: =B8/B6 -> 0.057226833 | C9: =C8/C6 -> 0.052558783 | D9: =D8/D6 -> 0.016770401 | E9: =E8/E6 -> 0.019190871 | L9: 2004 | M9: =SUMPRODUCT(--(TEXT($A$20:$A$5803,"yyyy")=$L9)) -> 168 | N9: =SUMPRODUCT((TEXT($A$20:$A$5803,"yyyy")=$L9)*$G$20:$G$5803) -> 11 | O9: =SUMPRODUCT((TEXT($A$20:$A$5803,"yyyy")=$L9)*$H$20:$H$5803) -> 8 | P9: =SUMPRODUCT((TEXT($A$20:$A$5803,"yyyy")=$L9)*$I$20:$I$5803) -> 1 | Q9: =SUMPRODUCT((TEXT($A$20:$A$5803,"yyyy")=$L9)*$J$20:$J$5803) -> 1
A10: Kupiec POF LR | B10: =-2*((B6-B8)*LN(Inputs!$B$8)+B8*LN(1-Inputs!$B$8)-((B6-B8)*LN(1-B9)+IF(B8>0,B8*LN(B9),0))) -> 6.088714 | C10: =-2*((C6-C8)*LN(Inputs!$B$8)+C8*LN(1-Inputs!$B$8)-((C6-C8)*LN(1-C9)+IF(C8>0,C8*LN(C9),0))) -> 0.78469934 | D10: =-2*((D6-D8)*LN(Inputs!$B$9)+D8*LN(1-Inputs!$B$9)-((D6-D8)*LN(1-D9)+IF(D8>0,D8*LN(D9),0))) -> 22.252317 | E10: =-2*((E6-E8)*LN(Inputs!$B$9)+E8*LN(1-Inputs!$B$9)-((E6-E8)*LN(1-E9)+IF(E8>0,E8*LN(E9),0))) -> 38.885673 | L10: 2005 | M10: =SUMPRODUCT(--(TEXT($A$20:$A$5803,"yyyy")=$L10)) -> 175 | N10: =SUMPRODUCT((TEXT($A$20:$A$5803,"yyyy")=$L10)*$G$20:$G$5803) -> 10 | O10: =SUMPRODUCT((TEXT($A$20:$A$5803,"yyyy")=$L10)*$H$20:$H$5803) -> 8 | P10: =SUMPRODUCT((TEXT($A$20:$A$5803,"yyyy")=$L10)*$I$20:$I$5803) -> 3 | Q10: =SUMPRODUCT((TEXT($A$20:$A$5803,"yyyy")=$L10)*$J$20:$J$5803) -> 3
A11: Kupiec p-value | B11: =CHIDIST(B10,1) -> 0.013604808 | C11: =CHIDIST(C10,1) -> 0.37570776 | D11: =CHIDIST(D10,1) -> 2.3907009e-06 | E11: =CHIDIST(E10,1) -> 4.4936661e-10 | L11: 2006 | M11: =SUMPRODUCT(--(TEXT($A$20:$A$5803,"yyyy")=$L11)) -> 204 | N11: =SUMPRODUCT((TEXT($A$20:$A$5803,"yyyy")=$L11)*$G$20:$G$5803) -> 14 | O11: =SUMPRODUCT((TEXT($A$20:$A$5803,"yyyy")=$L11)*$H$20:$H$5803) -> 14 | P11: =SUMPRODUCT((TEXT($A$20:$A$5803,"yyyy")=$L11)*$I$20:$I$5803) -> 5 | Q11: =SUMPRODUCT((TEXT($A$20:$A$5803,"yyyy")=$L11)*$J$20:$J$5803) -> 5
A12: Kupiec result (5%) | B12: =IF(B11>0.05,"Pass","Reject") -> Reject | C12: =IF(C11>0.05,"Pass","Reject") -> Pass | D12: =IF(D11>0.05,"Pass","Reject") -> Reject | E12: =IF(E11>0.05,"Pass","Reject") -> Reject | L12: 2007 | M12: =SUMPRODUCT(--(TEXT($A$20:$A$5803,"yyyy")=$L12)) -> 243 | N12: =SUMPRODUCT((TEXT($A$20:$A$5803,"yyyy")=$L12)*$G$20:$G$5803) -> 13 | O12: =SUMPRODUCT((TEXT($A$20:$A$5803,"yyyy")=$L12)*$H$20:$H$5803) -> 16 | P12: =SUMPRODUCT((TEXT($A$20:$A$5803,"yyyy")=$L12)*$I$20:$I$5803) -> 5 | Q12: =SUMPRODUCT((TEXT($A$20:$A$5803,"yyyy")=$L12)*$J$20:$J$5803) -> 2
A13: Exceptions, last 250 days | B13: =SUM(G5554:G5803) -> 22 | C13: =SUM(H5554:H5803) -> 18 | D13: =SUM(I5554:I5803) -> 8 | E13: =SUM(J5554:J5803) -> 9 | L13: 2008 | M13: =SUMPRODUCT(--(TEXT($A$20:$A$5803,"yyyy")=$L13)) -> 253 | N13: =SUMPRODUCT((TEXT($A$20:$A$5803,"yyyy")=$L13)*$G$20:$G$5803) -> 32 | O13: =SUMPRODUCT((TEXT($A$20:$A$5803,"yyyy")=$L13)*$H$20:$H$5803) -> 25 | P13: =SUMPRODUCT((TEXT($A$20:$A$5803,"yyyy")=$L13)*$I$20:$I$5803) -> 11 | Q13: =SUMPRODUCT((TEXT($A$20:$A$5803,"yyyy")=$L13)*$J$20:$J$5803) -> 10
A14: Basel traffic light (CL2 only) | B14: ="n/a" -> n/a | C14: ="n/a" -> n/a | D14: =IF(D13<=4,"Green",IF(D13<=9,"Yellow","Red")) -> Yellow | E14: =IF(E13<=4,"Green",IF(E13<=9,"Yellow","Red")) -> Yellow | L14: 2009 | M14: =SUMPRODUCT(--(TEXT($A$20:$A$5803,"yyyy")=$L14)) -> 250 | N14: =SUMPRODUCT((TEXT($A$20:$A$5803,"yyyy")=$L14)*$G$20:$G$5803) -> 1 | O14: =SUMPRODUCT((TEXT($A$20:$A$5803,"yyyy")=$L14)*$H$20:$H$5803) -> 0 | P14: =SUMPRODUCT((TEXT($A$20:$A$5803,"yyyy")=$L14)*$I$20:$I$5803) -> 0 | Q14: =SUMPRODUCT((TEXT($A$20:$A$5803,"yyyy")=$L14)*$J$20:$J$5803) -> 0
A15: Basel zones for 250 days at 99%: Green 0-4, Yellow 5-9, Red 10+. Kupiec tests whether the exception rate over the full history equals 1 - confidence. | L15: 2010 | M15: =SUMPRODUCT(--(TEXT($A$20:$A$5803,"yyyy")=$L15)) -> 252 | N15: =SUMPRODUCT((TEXT($A$20:$A$5803,"yyyy")=$L15)*$G$20:$G$5803) -> 12 | O15: =SUMPRODUCT((TEXT($A$20:$A$5803,"yyyy")=$L15)*$H$20:$H$5803) -> 10 | P15: =SUMPRODUCT((TEXT($A$20:$A$5803,"yyyy")=$L15)*$I$20:$I$5803) -> 5 | Q15: =SUMPRODUCT((TEXT($A$20:$A$5803,"yyyy")=$L15)*$J$20:$J$5803) -> 3
L16: 2011 | M16: =SUMPRODUCT(--(TEXT($A$20:$A$5803,"yyyy")=$L16)) -> 209 | N16: =SUMPRODUCT((TEXT($A$20:$A$5803,"yyyy")=$L16)*$G$20:$G$5803) -> 23 | O16: =SUMPRODUCT((TEXT($A$20:$A$5803,"yyyy")=$L16)*$H$20:$H$5803) -> 21 | P16: =SUMPRODUCT((TEXT($A$20:$A$5803,"yyyy")=$L16)*$I$20:$I$5803) -> 7 | Q16: =SUMPRODUCT((TEXT($A$20:$A$5803,"yyyy")=$L16)*$J$20:$J$5803) -> 7
L17: 2012 | M17: =SUMPRODUCT(--(TEXT($A$20:$A$5803,"yyyy")=$L17)) -> 249 | N17: =SUMPRODUCT((TEXT($A$20:$A$5803,"yyyy")=$L17)*$G$20:$G$5803) -> 8 | O17: =SUMPRODUCT((TEXT($A$20:$A$5803,"yyyy")=$L17)*$H$20:$H$5803) -> 5 | P17: =SUMPRODUCT((TEXT($A$20:$A$5803,"yyyy")=$L17)*$I$20:$I$5803) -> 2 | Q17: =SUMPRODUCT((TEXT($A$20:$A$5803,"yyyy")=$L17)*$J$20:$J$5803) -> 1
L18: 2013 | M18: =SUMPRODUCT(--(TEXT($A$20:$A$5803,"yyyy")=$L18)) -> 250 | N18: =SUMPRODUCT((TEXT($A$20:$A$5803,"yyyy")=$L18)*$G$20:$G$5803) -> 10 | O18: =SUMPRODUCT((TEXT($A$20:$A$5803,"yyyy")=$L18)*$H$20:$H$5803) -> 11 | P18: =SUMPRODUCT((TEXT($A$20:$A$5803,"yyyy")=$L18)*$I$20:$I$5803) -> 2 | Q18: =SUMPRODUCT((TEXT($A$20:$A$5803,"yyyy")=$L18)*$J$20:$J$5803) -> 2
A19: Date | B19: Actual P&L ($) | C19: Hist VaR CL1 | D19: Param VaR CL1 | E19: Hist VaR CL2 | F19: Param VaR CL2 | G19: Exc H1 | H19: Exc P1 | I19: Exc H2 | J19: Exc P2 | L19: 2014 | M19: =SUMPRODUCT(--(TEXT($A$20:$A$5803,"yyyy")=$L19)) -> 248 | N19: =SUMPRODUCT((TEXT($A$20:$A$5803,"yyyy")=$L19)*$G$20:$G$5803) -> 18 | O19: =SUMPRODUCT((TEXT($A$20:$A$5803,"yyyy")=$L19)*$H$20:$H$5803) -> 18 | P19: =SUMPRODUCT((TEXT($A$20:$A$5803,"yyyy")=$L19)*$I$20:$I$5803) -> 9 | Q19: =SUMPRODUCT((TEXT($A$20:$A$5803,"yyyy")=$L19)*$J$20:$J$5803) -> 7
A20: =Prices_MTM!A253 -> 37041 | B20: =Prices_MTM!I253 -> 4500 | C20: =-PERCENTILE(Prices_MTM!I3:I252,1-Inputs!$B$8) -> 127350 | D20: =NORMSINV(Inputs!$B$8)*STDEV(Prices_MTM!I3:I252) -> 131273.85 | E20: =-PERCENTILE(Prices_MTM!I3:I252,1-Inputs!$B$9) -> 268675 | F20: =NORMSINV(Inputs!$B$9)*STDEV(Prices_MTM!I3:I252) -> 185663.12 | G20: =IF(-B20>C20,1,0) -> 0 | H20: =IF(-B20>D20,1,0) -> 0 | I20: =IF(-B20>E20,1,0) -> 0 | J20: =IF(-B20>F20,1,0) -> 0 | L20: 2015 | M20: =SUMPRODUCT(--(TEXT($A$20:$A$5803,"yyyy")=$L20)) -> 243 | N20: =SUMPRODUCT((TEXT($A$20:$A$5803,"yyyy")=$L20)*$G$20:$G$5803) -> 11 | O20: =SUMPRODUCT((TEXT($A$20:$A$5803,"yyyy")=$L20)*$H$20:$H$5803) -> 10 | P20: =SUMPRODUCT((TEXT($A$20:$A$5803,"yyyy")=$L20)*$I$20:$I$5803) -> 0 | Q20: =SUMPRODUCT((TEXT($A$20:$A$5803,"yyyy")=$L20)*$J$20:$J$5803) -> 4
A21: =Prices_MTM!A254 -> 37042 | B21: =Prices_MTM!I254 -> -13500 | C21: =-PERCENTILE(Prices_MTM!I4:I253,1-Inputs!$B$8) -> 127350 | D21: =NORMSINV(Inputs!$B$8)*STDEV(Prices_MTM!I4:I253) -> 131009.97 | E21: =-PERCENTILE(Prices_MTM!I4:I253,1-Inputs!$B$9) -> 268675 | F21: =NORMSINV(Inputs!$B$9)*STDEV(Prices_MTM!I4:I253) -> 185289.9 | G21: =IF(-B21>C21,1,0) -> 0 | H21: =IF(-B21>D21,1,0) -> 0 | I21: =IF(-B21>E21,1,0) -> 0 | J21: =IF(-B21>F21,1,0) -> 0 | L21: 2016 | M21: =SUMPRODUCT(--(TEXT($A$20:$A$5803,"yyyy")=$L21)) -> 251 | N21: =SUMPRODUCT((TEXT($A$20:$A$5803,"yyyy")=$L21)*$G$20:$G$5803) -> 7 | O21: =SUMPRODUCT((TEXT($A$20:$A$5803,"yyyy")=$L21)*$H$20:$H$5803) -> 7 | P21: =SUMPRODUCT((TEXT($A$20:$A$5803,"yyyy")=$L21)*$I$20:$I$5803) -> 3 | Q21: =SUMPRODUCT((TEXT($A$20:$A$5803,"yyyy")=$L21)*$J$20:$J$5803) -> 1
A22: =Prices_MTM!A255 -> 37046 | B22: =Prices_MTM!I255 -> -45000 | C22: =-PERCENTILE(Prices_MTM!I5:I254,1-Inputs!$B$8) -> 127350 | D22: =NORMSINV(Inputs!$B$8)*STDEV(Prices_MTM!I5:I254) -> 130998.06 | E22: =-PERCENTILE(Prices_MTM!I5:I254,1-Inputs!$B$9) -> 268675 | F22: =NORMSINV(Inputs!$B$9)*STDEV(Prices_MTM!I5:I254) -> 185273.06 | G22: =IF(-B22>C22,1,0) -> 0 | H22: =IF(-B22>D22,1,0) -> 0 | I22: =IF(-B22>E22,1,0) -> 0 | J22: =IF(-B22>F22,1,0) -> 0 | L22: 2017 | M22: =SUMPRODUCT(--(TEXT($A$20:$A$5803,"yyyy")=$L22)) -> 249 | N22: =SUMPRODUCT((TEXT($A$20:$A$5803,"yyyy")=$L22)*$G$20:$G$5803) -> 11 | O22: =SUMPRODUCT((TEXT($A$20:$A$5803,"yyyy")=$L22)*$H$20:$H$5803) -> 12 | P22: =SUMPRODUCT((TEXT($A$20:$A$5803,"yyyy")=$L22)*$I$20:$I$5803) -> 2 | Q22: =SUMPRODUCT((TEXT($A$20:$A$5803,"yyyy")=$L22)*$J$20:$J$5803) -> 6
A23: =Prices_MTM!A256 -> 37048 | B23: =Prices_MTM!I256 -> -47000 | C23: =-PERCENTILE(Prices_MTM!I6:I255,1-Inputs!$B$8) -> 127350 | D23: =NORMSINV(Inputs!$B$8)*STDEV(Prices_MTM!I6:I255) -> 131079.37 | E23: =-PERCENTILE(Prices_MTM!I6:I255,1-Inputs!$B$9) -> 268675 | F23: =NORMSINV(Inputs!$B$9)*STDEV(Prices_MTM!I6:I255) -> 185388.06 | G23: =IF(-B23>C23,1,0) -> 0 | H23: =IF(-B23>D23,1,0) -> 0 | I23: =IF(-B23>E23,1,0) -> 0 | J23: =IF(-B23>F23,1,0) -> 0 | L23: 2018 | M23: =SUMPRODUCT(--(TEXT($A$20:$A$5803,"yyyy")=$L23)) -> 246 | N23: =SUMPRODUCT((TEXT($A$20:$A$5803,"yyyy")=$L23)*$G$20:$G$5803) -> 23 | O23: =SUMPRODUCT((TEXT($A$20:$A$5803,"yyyy")=$L23)*$H$20:$H$5803) -> 24 | P23: =SUMPRODUCT((TEXT($A$20:$A$5803,"yyyy")=$L23)*$I$20:$I$5803) -> 5 | Q23: =SUMPRODUCT((TEXT($A$20:$A$5803,"yyyy")=$L23)*$J$20:$J$5803) -> 10
A24: =Prices_MTM!A257 -> 37049 | B24: =Prices_MTM!I257 -> 44000 | C24: =-PERCENTILE(Prices_MTM!I7:I256,1-Inputs!$B$8) -> 127350 | D24: =NORMSINV(Inputs!$B$8)*STDEV(Prices_MTM!I7:I256) -> 131153.11 | E24: =-PERCENTILE(Prices_MTM!I7:I256,1-Inputs!$B$9) -> 268675 | F24: =NORMSINV(Inputs!$B$9)*STDEV(Prices_MTM!I7:I256) -> 185492.34 | G24: =IF(-B24>C24,1,0) -> 0 | H24: =IF(-B24>D24,1,0) -> 0 | I24: =IF(-B24>E24,1,0) -> 0 | J24: =IF(-B24>F24,1,0) -> 0 | L24: 2019 | M24: =SUMPRODUCT(--(TEXT($A$20:$A$5803,"yyyy")=$L24)) -> 250 | N24: =SUMPRODUCT((TEXT($A$20:$A$5803,"yyyy")=$L24)*$G$20:$G$5803) -> 7 | O24: =SUMPRODUCT((TEXT($A$20:$A$5803,"yyyy")=$L24)*$H$20:$H$5803) -> 7 | P24: =SUMPRODUCT((TEXT($A$20:$A$5803,"yyyy")=$L24)*$I$20:$I$5803) -> 2 | Q24: =SUMPRODUCT((TEXT($A$20:$A$5803,"yyyy")=$L24)*$J$20:$J$5803) -> 2
A25: =Prices_MTM!A258 -> 37054 | B25: =Prices_MTM!I258 -> 98000 | C25: =-PERCENTILE(Prices_MTM!I8:I257,1-Inputs!$B$8) -> 127350 | D25: =NORMSINV(Inputs!$B$8)*STDEV(Prices_MTM!I8:I257) -> 131167.04 | E25: =-PERCENTILE(Prices_MTM!I8:I257,1-Inputs!$B$9) -> 268675 | F25: =NORMSINV(Inputs!$B$9)*STDEV(Prices_MTM!I8:I257) -> 185512.04 | G25: =IF(-B25>C25,1,0) -> 0 | H25: =IF(-B25>D25,1,0) -> 0 | I25: =IF(-B25>E25,1,0) -> 0 | J25: =IF(-B25>F25,1,0) -> 0 | L25: 2020 | M25: =SUMPRODUCT(--(TEXT($A$20:$A$5803,"yyyy")=$L25)) -> 249 | N25: =SUMPRODUCT((TEXT($A$20:$A$5803,"yyyy")=$L25)*$G$20:$G$5803) -> 14 | O25: =SUMPRODUCT((TEXT($A$20:$A$5803,"yyyy")=$L25)*$H$20:$H$5803) -> 12 | P25: =SUMPRODUCT((TEXT($A$20:$A$5803,"yyyy")=$L25)*$I$20:$I$5803) -> 5 | Q25: =SUMPRODUCT((TEXT($A$20:$A$5803,"yyyy")=$L25)*$J$20:$J$5803) -> 7
A26: =Prices_MTM!A259 -> 37055 | B26: =Prices_MTM!I259 -> -37000 | C26: =-PERCENTILE(Prices_MTM!I9:I258,1-Inputs!$B$8) -> 127350 | D26: =NORMSINV(Inputs!$B$8)*STDEV(Prices_MTM!I9:I258) -> 131534.59 | E26: =-PERCENTILE(Prices_MTM!I9:I258,1-Inputs!$B$9) -> 268675 | F26: =NORMSINV(Inputs!$B$9)*STDEV(Prices_MTM!I9:I258) -> 186031.88 | G26: =IF(-B26>C26,1,0) -> 0 | H26: =IF(-B26>D26,1,0) -> 0 | I26: =IF(-B26>E26,1,0) -> 0 | J26: =IF(-B26>F26,1,0) -> 0 | L26: 2021 | M26: =SUMPRODUCT(--(TEXT($A$20:$A$5803,"yyyy")=$L26)) -> 246 | N26: =SUMPRODUCT((TEXT($A$20:$A$5803,"yyyy")=$L26)*$G$20:$G$5803) -> 18 | O26: =SUMPRODUCT((TEXT($A$20:$A$5803,"yyyy")=$L26)*$H$20:$H$5803) -> 15 | P26: =SUMPRODUCT((TEXT($A$20:$A$5803,"yyyy")=$L26)*$I$20:$I$5803) -> 5 | Q26: =SUMPRODUCT((TEXT($A$20:$A$5803,"yyyy")=$L26)*$J$20:$J$5803) -> 5
A27: =Prices_MTM!A260 -> 37056 | B27: =Prices_MTM!I260 -> 62500 | C27: =-PERCENTILE(Prices_MTM!I10:I259,1-Inputs!$B$8) -> 127350 | D27: =NORMSINV(Inputs!$B$8)*STDEV(Prices_MTM!I10:I259) -> 130190.01 | E27: =-PERCENTILE(Prices_MTM!I10:I259,1-Inputs!$B$9) -> 268675 | F27: =NORMSINV(Inputs!$B$9)*STDEV(Prices_MTM!I10:I259) -> 184130.21 | G27: =IF(-B27>C27,1,0) -> 0 | H27: =IF(-B27>D27,1,0) -> 0 | I27: =IF(-B27>E27,1,0) -> 0 | J27: =IF(-B27>F27,1,0) -> 0 | L27: 2022 | M27: =SUMPRODUCT(--(TEXT($A$20:$A$5803,"yyyy")=$L27)) -> 245 | N27: =SUMPRODUCT((TEXT($A$20:$A$5803,"yyyy")=$L27)*$G$20:$G$5803) -> 22 | O27: =SUMPRODUCT((TEXT($A$20:$A$5803,"yyyy")=$L27)*$H$20:$H$5803) -> 22 | P27: =SUMPRODUCT((TEXT($A$20:$A$5803,"yyyy")=$L27)*$I$20:$I$5803) -> 5 | Q27: =SUMPRODUCT((TEXT($A$20:$A$5803,"yyyy")=$L27)*$J$20:$J$5803) -> 8
A28: =Prices_MTM!A261 -> 37057 | B28: =Prices_MTM!I261 -> -41500 | C28: =-PERCENTILE(Prices_MTM!I11:I260,1-Inputs!$B$8) -> 127350 | D28: =NORMSINV(Inputs!$B$8)*STDEV(Prices_MTM!I11:I260) -> 130338.18 | E28: =-PERCENTILE(Prices_MTM!I11:I260,1-Inputs!$B$9) -> 268675 | F28: =NORMSINV(Inputs!$B$9)*STDEV(Prices_MTM!I11:I260) -> 184339.77 | G28: =IF(-B28>C28,1,0) -> 0 | H28: =IF(-B28>D28,1,0) -> 0 | I28: =IF(-B28>E28,1,0) -> 0 | J28: =IF(-B28>F28,1,0) -> 0 | L28: 2023 | M28: =SUMPRODUCT(--(TEXT($A$20:$A$5803,"yyyy")=$L28)) -> 243 | N28: =SUMPRODUCT((TEXT($A$20:$A$5803,"yyyy")=$L28)*$G$20:$G$5803) -> 7 | O28: =SUMPRODUCT((TEXT($A$20:$A$5803,"yyyy")=$L28)*$H$20:$H$5803) -> 7 | P28: =SUMPRODUCT((TEXT($A$20:$A$5803,"yyyy")=$L28)*$I$20:$I$5803) -> 3 | Q28: =SUMPRODUCT((TEXT($A$20:$A$5803,"yyyy")=$L28)*$J$20:$J$5803) -> 3
A29: =Prices_MTM!A262 -> 37060 | B29: =Prices_MTM!I262 -> -71000 | C29: =-PERCENTILE(Prices_MTM!I12:I261,1-Inputs!$B$8) -> 127350 | D29: =NORMSINV(Inputs!$B$8)*STDEV(Prices_MTM!I12:I261) -> 130294.38 | E29: =-PERCENTILE(Prices_MTM!I12:I261,1-Inputs!$B$9) -> 268675 | F29: =NORMSINV(Inputs!$B$9)*STDEV(Prices_MTM!I12:I261) -> 184277.83 | G29: =IF(-B29>C29,1,0) -> 0 | H29: =IF(-B29>D29,1,0) -> 0 | I29: =IF(-B29>E29,1,0) -> 0 | J29: =IF(-B29>F29,1,0) -> 0 | L29: 2024 | M29: =SUMPRODUCT(--(TEXT($A$20:$A$5803,"yyyy")=$L29)) -> 246 | N29: =SUMPRODUCT((TEXT($A$20:$A$5803,"yyyy")=$L29)*$G$20:$G$5803) -> 14 | O29: =SUMPRODUCT((TEXT($A$20:$A$5803,"yyyy")=$L29)*$H$20:$H$5803) -> 14 | P29: =SUMPRODUCT((TEXT($A$20:$A$5803,"yyyy")=$L29)*$I$20:$I$5803) -> 1 | Q29: =SUMPRODUCT((TEXT($A$20:$A$5803,"yyyy")=$L29)*$J$20:$J$5803) -> 4
A30: =Prices_MTM!A263 -> 37061 | B30: =Prices_MTM!I263 -> 40500 | C30: =-PERCENTILE(Prices_MTM!I13:I262,1-Inputs!$B$8) -> 127350 | D30: =NORMSINV(Inputs!$B$8)*STDEV(Prices_MTM!I13:I262) -> 130428.8 | E30: =-PERCENTILE(Prices_MTM!I13:I262,1-Inputs!$B$9) -> 268675 | F30: =NORMSINV(Inputs!$B$9)*STDEV(Prices_MTM!I13:I262) -> 184467.94 | G30: =IF(-B30>C30,1,0) -> 0 | H30: =IF(-B30>D30,1,0) -> 0 | I30: =IF(-B30>E30,1,0) -> 0 | J30: =IF(-B30>F30,1,0) -> 0 | L30: 2025 | M30: =SUMPRODUCT(--(TEXT($A$20:$A$5803,"yyyy")=$L30)) -> 244 | N30: =SUMPRODUCT((TEXT($A$20:$A$5803,"yyyy")=$L30)*$G$20:$G$5803) -> 4 | O30: =SUMPRODUCT((TEXT($A$20:$A$5803,"yyyy")=$L30)*$H$20:$H$5803) -> 5 | P30: =SUMPRODUCT((TEXT($A$20:$A$5803,"yyyy")=$L30)*$I$20:$I$5803) -> 3 | Q30: =SUMPRODUCT((TEXT($A$20:$A$5803,"yyyy")=$L30)*$J$20:$J$5803) -> 3
A31: =Prices_MTM!A264 -> 37062 | B31: =Prices_MTM!I264 -> -75000 | C31: =-PERCENTILE(Prices_MTM!I14:I263,1-Inputs!$B$8) -> 127350 | D31: =NORMSINV(Inputs!$B$8)*STDEV(Prices_MTM!I14:I263) -> 130374.55 | E31: =-PERCENTILE(Prices_MTM!I14:I263,1-Inputs!$B$9) -> 268675 | F31: =NORMSINV(Inputs!$B$9)*STDEV(Prices_MTM!I14:I263) -> 184391.21 | G31: =IF(-B31>C31,1,0) -> 0 | H31: =IF(-B31>D31,1,0) -> 0 | I31: =IF(-B31>E31,1,0) -> 0 | J31: =IF(-B31>F31,1,0) -> 0 | L31: 2026 | M31: =SUMPRODUCT(--(TEXT($A$20:$A$5803,"yyyy")=$L31)) -> 183 | N31: =SUMPRODUCT((TEXT($A$20:$A$5803,"yyyy")=$L31)*$G$20:$G$5803) -> 22 | O31: =SUMPRODUCT((TEXT($A$20:$A$5803,"yyyy")=$L31)*$H$20:$H$5803) -> 18 | P31: =SUMPRODUCT((TEXT($A$20:$A$5803,"yyyy")=$L31)*$I$20:$I$5803) -> 8 | Q31: =SUMPRODUCT((TEXT($A$20:$A$5803,"yyyy")=$L31)*$J$20:$J$5803) -> 9
A32: =Prices_MTM!A265 -> 37063 | B32: =Prices_MTM!I265 -> 10000 | C32: =-PERCENTILE(Prices_MTM!I15:I264,1-Inputs!$B$8) -> 122150 | D32: =NORMSINV(Inputs!$B$8)*STDEV(Prices_MTM!I15:I264) -> 127085.29 | E32: =-PERCENTILE(Prices_MTM!I15:I264,1-Inputs!$B$9) -> 244550 | F32: =NORMSINV(Inputs!$B$9)*STDEV(Prices_MTM!I15:I264) -> 179739.15 | G32: =IF(-B32>C32,1,0) -> 0 | H32: =IF(-B32>D32,1,0) -> 0 | I32: =IF(-B32>E32,1,0) -> 0 | J32: =IF(-B32>F32,1,0) -> 0
A33: =Prices_MTM!A266 -> 37064 | B33: =Prices_MTM!I266 -> 9000 | C33: =-PERCENTILE(Prices_MTM!I16:I265,1-Inputs!$B$8) -> 122150 | D33: =NORMSINV(Inputs!$B$8)*STDEV(Prices_MTM!I16:I265) -> 127070.55 | E33: =-PERCENTILE(Prices_MTM!I16:I265,1-Inputs!$B$9) -> 244550 | F33: =NORMSINV(Inputs!$B$9)*STDEV(Prices_MTM!I16:I265) -> 179718.3 | G33: =IF(-B33>C33,1,0) -> 0 | H33: =IF(-B33>D33,1,0) -> 0 | I33: =IF(-B33>E33,1,0) -> 0 | J33: =IF(-B33>F33,1,0) -> 0
A34: =Prices_MTM!A267 -> 37067 | B34: =Prices_MTM!I267 -> -16000 | C34: =-PERCENTILE(Prices_MTM!I17:I266,1-Inputs!$B$8) -> 122150 | D34: =NORMSINV(Inputs!$B$8)*STDEV(Prices_MTM!I17:I266) -> 127066.15 | E34: =-PERCENTILE(Prices_MTM!I17:I266,1-Inputs!$B$9) -> 244550 | F34: =NORMSINV(Inputs!$B$9)*STDEV(Prices_MTM!I17:I266) -> 179712.07 | G34: =IF(-B34>C34,1,0) -> 0 | H34: =IF(-B34>D34,1,0) -> 0 | I34: =IF(-B34>E34,1,0) -> 0 | J34: =IF(-B34>F34,1,0) -> 0
A35: =Prices_MTM!A268 -> 37068 | B35: =Prices_MTM!I268 -> -29000 | C35: =-PERCENTILE(Prices_MTM!I18:I267,1-Inputs!$B$8) -> 122150 | D35: =NORMSINV(Inputs!$B$8)*STDEV(Prices_MTM!I18:I267) -> 126970.39 | E35: =-PERCENTILE(Prices_MTM!I18:I267,1-Inputs!$B$9) -> 244550 | F35: =NORMSINV(Inputs!$B$9)*STDEV(Prices_MTM!I18:I267) -> 179576.65 | G35: =IF(-B35>C35,1,0) -> 0 | H35: =IF(-B35>D35,1,0) -> 0 | I35: =IF(-B35>E35,1,0) -> 0 | J35: =IF(-B35>F35,1,0) -> 0
A36: =Prices_MTM!A269 -> 37069 | B36: =Prices_MTM!I269 -> -59500 | C36: =-PERCENTILE(Prices_MTM!I19:I268,1-Inputs!$B$8) -> 122150 | D36: =NORMSINV(Inputs!$B$8)*STDEV(Prices_MTM!I19:I268) -> 126821.16 | E36: =-PERCENTILE(Prices_MTM!I19:I268,1-Inputs!$B$9) -> 244550 | F36: =NORMSINV(Inputs!$B$9)*STDEV(Prices_MTM!I19:I268) -> 179365.59 | G36: =IF(-B36>C36,1,0) -> 0 | H36: =IF(-B36>D36,1,0) -> 0 | I36: =IF(-B36>E36,1,0) -> 0 | J36: =IF(-B36>F36,1,0) -> 0
A37: =Prices_MTM!A270 -> 37071 | B37: =Prices_MTM!I270 -> 72000 | C37: =-PERCENTILE(Prices_MTM!I20:I269,1-Inputs!$B$8) -> 122150 | D37: =NORMSINV(Inputs!$B$8)*STDEV(Prices_MTM!I20:I269) -> 126854.02 | E37: =-PERCENTILE(Prices_MTM!I20:I269,1-Inputs!$B$9) -> 244550 | F37: =NORMSINV(Inputs!$B$9)*STDEV(Prices_MTM!I20:I269) -> 179412.06 | G37: =IF(-B37>C37,1,0) -> 0 | H37: =IF(-B37>D37,1,0) -> 0 | I37: =IF(-B37>E37,1,0) -> 0 | J37: =IF(-B37>F37,1,0) -> 0
A38: =Prices_MTM!A271 -> 37075 | B38: =Prices_MTM!I271 -> 23500 | C38: =-PERCENTILE(Prices_MTM!I21:I270,1-Inputs!$B$8) -> 122150 | D38: =NORMSINV(Inputs!$B$8)*STDEV(Prices_MTM!I21:I270) -> 126982.9 | E38: =-PERCENTILE(Prices_MTM!I21:I270,1-Inputs!$B$9) -> 244550 | F38: =NORMSINV(Inputs!$B$9)*STDEV(Prices_MTM!I21:I270) -> 179594.34 | G38: =IF(-B38>C38,1,0) -> 0 | H38: =IF(-B38>D38,1,0) -> 0 | I38: =IF(-B38>E38,1,0) -> 0 | J38: =IF(-B38>F38,1,0) -> 0
A39: =Prices_MTM!A272 -> 37077 | B39: =Prices_MTM!I272 -> 72500 | C39: =-PERCENTILE(Prices_MTM!I22:I271,1-Inputs!$B$8) -> 122150 | D39: =NORMSINV(Inputs!$B$8)*STDEV(Prices_MTM!I22:I271) -> 126809.45 | E39: =-PERCENTILE(Prices_MTM!I22:I271,1-Inputs!$B$9) -> 244550 | F39: =NORMSINV(Inputs!$B$9)*STDEV(Prices_MTM!I22:I271) -> 179349.03 | G39: =IF(-B39>C39,1,0) -> 0 | H39: =IF(-B39>D39,1,0) -> 0 | I39: =IF(-B39>E39,1,0) -> 0 | J39: =IF(-B39>F39,1,0) -> 0
A40: =Prices_MTM!A273 -> 37078 | B40: =Prices_MTM!I273 -> 60000 | C40: =-PERCENTILE(Prices_MTM!I23:I272,1-Inputs!$B$8) -> 122150 | D40: =NORMSINV(Inputs!$B$8)*STDEV(Prices_MTM!I23:I272) -> 126796.8 | E40: =-PERCENTILE(Prices_MTM!I23:I272,1-Inputs!$B$9) -> 244550 | F40: =NORMSINV(Inputs!$B$9)*STDEV(Prices_MTM!I23:I272) -> 179331.14 | G40: =IF(-B40>C40,1,0) -> 0 | H40: =IF(-B40>D40,1,0) -> 0 | I40: =IF(-B40>E40,1,0) -> 0 | J40: =IF(-B40>F40,1,0) -> 0
A41: =Prices_MTM!A274 -> 37081 | B41: =Prices_MTM!I274 -> 1000 | C41: =-PERCENTILE(Prices_MTM!I24:I273,1-Inputs!$B$8) -> 122150 | D41: =NORMSINV(Inputs!$B$8)*STDEV(Prices_MTM!I24:I273) -> 126647.91 | E41: =-PERCENTILE(Prices_MTM!I24:I273,1-Inputs!$B$9) -> 244550 | F41: =NORMSINV(Inputs!$B$9)*STDEV(Prices_MTM!I24:I273) -> 179120.56 | G41: =IF(-B41>C41,1,0) -> 0 | H41: =IF(-B41>D41,1,0) -> 0 | I41: =IF(-B41>E41,1,0) -> 0 | J41: =IF(-B41>F41,1,0) -> 0
...

Sheet Stress
A1: Stress scenarios on today's position
A2: Historical shocks are measured from the price history between the two dates; hypothetical shocks are set by hand (blue).
A4: Today's WTI ($/bbl) | B4: =VaR!B11 -> 96.16
A5: Today's Brent ($/bbl) | B5: =VaR!B12 -> 113.96
A6: 99% historical VaR ($) | B6: =VaR!D29 -> 474615
A7: Units: % = relative move, $ = absolute $/bbl move, level = price set to the value
A9: Scenario | B9: Start date | C9: End date | D9: WTI unit | E9: WTI shock | F9: Brent unit | G9: Brent shock | H9: WTI stressed | I9: Brent stressed | J9: P&L WTI ($) | K9: P&L Brent ($) | L9: P&L total ($) | M9: x 99% VaR | N9: Note
A10: Negative WTI (20 Apr 2020, 1 day) | B10: 43938 | C10: 43941 | D10: $ | E10: =IF(D10="%",INDEX(Prices_MTM!B:B,MATCH($C10,Prices_MTM!$A:$A,0))/INDEX(Prices_MTM!B:B,MATCH($B10,Prices_MTM!$A:$A,0))-1,INDEX(Prices_MTM!B:B,MATCH($C10,Prices_MTM!$A:$A,0))-INDEX(Prices_MTM!B:B,MATCH($B10,Prices_MTM!$A:$A,0))) -> -55.29 | F10: $ | G10: =IF(F10="%",INDEX(Prices_MTM!C:C,MATCH($C10,Prices_MTM!$A:$A,0))/INDEX(Prices_MTM!C:C,MATCH($B10,Prices_MTM!$A:$A,0))-1,INDEX(Prices_MTM!C:C,MATCH($C10,Prices_MTM!$A:$A,0))-INDEX(Prices_MTM!C:C,MATCH($B10,Prices_MTM!$A:$A,0))) -> -2.39 | H10: =IF(D10="%",$B$4*(1+E10),IF(D10="$",$B$4+E10,E10)) -> 40.87 | I10: =IF(F10="%",$B$5*(1+G10),IF(F10="$",$B$5+G10,G10)) -> 111.57 | J10: =Inputs!$B$5*(H10-$B$4) -> -5529000 | K10: =Inputs!$B$6*(I10-$B$5) -> 119500 | L10: =J10+K10 -> -5409500 | M10: =L10/$B$6 -> -11.397659 | N10: Applied in $ since % change through zero is meaningless.
A11: COVID / OPEC+ price war (9 Mar 2020, 1 day) | B11: 43896 | C11: 43899 | D11: % | E11: =IF(D11="%",INDEX(Prices_MTM!B:B,MATCH($C11,Prices_MTM!$A:$A,0))/INDEX(Prices_MTM!B:B,MATCH($B11,Prices_MTM!$A:$A,0))-1,INDEX(Prices_MTM!B:B,MATCH($C11,Prices_MTM!$A:$A,0))-INDEX(Prices_MTM!B:B,MATCH($B11,Prices_MTM!$A:$A,0))) -> -0.24526009 | F11: % | G11: =IF(F11="%",INDEX(Prices_MTM!C:C,MATCH($C11,Prices_MTM!$A:$A,0))/INDEX(Prices_MTM!C:C,MATCH($B11,Prices_MTM!$A:$A,0))-1,INDEX(Prices_MTM!C:C,MATCH($C11,Prices_MTM!$A:$A,0))-INDEX(Prices_MTM!C:C,MATCH($B11,Prices_MTM!$A:$A,0))) -> -0.2252193 | H11: =IF(D11="%",$B$4*(1+E11),IF(D11="$",$B$4+E11,E11)) -> 72.57579 | I11: =IF(F11="%",$B$5*(1+G11),IF(F11="$",$B$5+G11,G11)) -> 88.294009 | J11: =Inputs!$B$5*(H11-$B$4) -> -2358421 | K11: =Inputs!$B$6*(I11-$B$5) -> 1283299.6 | L11: =J11+K11 -> -1075121.4 | M11: =L11/$B$6 -> -2.2652496 | N11: Saudi-Russia price war + COVID demand shock.
A12: 2022 Russia spike (24 Feb - 8 Mar 2022) | B12: 44615 | C12: 44628 | D12: % | E12: =IF(D12="%",INDEX(Prices_MTM!B:B,MATCH($C12,Prices_MTM!$A:$A,0))/INDEX(Prices_MTM!B:B,MATCH($B12,Prices_MTM!$A:$A,0))-1,INDEX(Prices_MTM!B:B,MATCH($C12,Prices_MTM!$A:$A,0))-INDEX(Prices_MTM!B:B,MATCH($B12,Prices_MTM!$A:$A,0))) -> 0.34187107 | F12: % | G12: =IF(F12="%",INDEX(Prices_MTM!C:C,MATCH($C12,Prices_MTM!$A:$A,0))/INDEX(Prices_MTM!C:C,MATCH($B12,Prices_MTM!$A:$A,0))-1,INDEX(Prices_MTM!C:C,MATCH($C12,Prices_MTM!$A:$A,0))-INDEX(Prices_MTM!C:C,MATCH($B12,Prices_MTM!$A:$A,0))) -> 0.3413234 | H12: =IF(D12="%",$B$4*(1+E12),IF(D12="$",$B$4+E12,E12)) -> 129.03432 | I12: =IF(F12="%",$B$5*(1+G12),IF(F12="$",$B$5+G12,G12)) -> 152.85721 | J12: =Inputs!$B$5*(H12-$B$4) -> 3287432.2 | K12: =Inputs!$B$6*(I12-$B$5) -> -1944860.7 | L12: =J12+K12 -> 1342571.5 | M12: =L12/$B$6 -> 2.828759 | N12: Spike: the short Brent leg loses, long WTI gains.
A13: 2022 spike reversal (9 Mar 2022, 1 day) | B13: 44628 | C13: 44629 | D13: % | E13: =IF(D13="%",INDEX(Prices_MTM!B:B,MATCH($C13,Prices_MTM!$A:$A,0))/INDEX(Prices_MTM!B:B,MATCH($B13,Prices_MTM!$A:$A,0))-1,INDEX(Prices_MTM!B:B,MATCH($C13,Prices_MTM!$A:$A,0))-INDEX(Prices_MTM!B:B,MATCH($B13,Prices_MTM!$A:$A,0))) -> -0.119945 | F13: % | G13: =IF(F13="%",INDEX(Prices_MTM!C:C,MATCH($C13,Prices_MTM!$A:$A,0))/INDEX(Prices_MTM!C:C,MATCH($B13,Prices_MTM!$A:$A,0))-1,INDEX(Prices_MTM!C:C,MATCH($C13,Prices_MTM!$A:$A,0))-INDEX(Prices_MTM!C:C,MATCH($B13,Prices_MTM!$A:$A,0))) -> -0.12464334 | H13: =IF(D13="%",$B$4*(1+E13),IF(D13="$",$B$4+E13,E13)) -> 84.626089 | I13: =IF(F13="%",$B$5*(1+G13),IF(F13="$",$B$5+G13,G13)) -> 99.755645 | J13: =Inputs!$B$5*(H13-$B$4) -> -1153391.1 | K13: =Inputs!$B$6*(I13-$B$5) -> 710217.75 | L13: =J13+K13 -> -443173.39 | M13: =L13/$B$6 -> -0.93375343 | N13: Largest 1-day drop after the 2022 peak.
A14: 2008 GFC collapse (Jul - Dec 2008) | B14: 39632 | C14: 39801 | D14: % | E14: =IF(D14="%",INDEX(Prices_MTM!B:B,MATCH($C14,Prices_MTM!$A:$A,0))/INDEX(Prices_MTM!B:B,MATCH($B14,Prices_MTM!$A:$A,0))-1,INDEX(Prices_MTM!B:B,MATCH($C14,Prices_MTM!$A:$A,0))-INDEX(Prices_MTM!B:B,MATCH($B14,Prices_MTM!$A:$A,0))) -> -0.77172941 | F14: % | G14: =IF(F14="%",INDEX(Prices_MTM!C:C,MATCH($C14,Prices_MTM!$A:$A,0))/INDEX(Prices_MTM!C:C,MATCH($B14,Prices_MTM!$A:$A,0))-1,INDEX(Prices_MTM!C:C,MATCH($C14,Prices_MTM!$A:$A,0))-INDEX(Prices_MTM!C:C,MATCH($B14,Prices_MTM!$A:$A,0))) -> -0.72546023 | H14: =IF(D14="%",$B$4*(1+E14),IF(D14="$",$B$4+E14,E14)) -> 21.9505 | I14: =IF(F14="%",$B$5*(1+G14),IF(F14="$",$B$5+G14,G14)) -> 31.286552 | J14: =Inputs!$B$5*(H14-$B$4) -> -7420950 | K14: =Inputs!$B$6*(I14-$B$5) -> 4133672.4 | L14: =J14+K14 -> -3287277.6 | M14: =L14/$B$6 -> -6.9261983 | N14: Multi-month: illustrates liquidity-horizon risk.
A15: 2014-15 OPEC supply glut | B15: 41810 | C15: 42017 | D15: % | E15: =IF(D15="%",INDEX(Prices_MTM!B:B,MATCH($C15,Prices_MTM!$A:$A,0))/INDEX(Prices_MTM!B:B,MATCH($B15,Prices_MTM!$A:$A,0))-1,INDEX(Prices_MTM!B:B,MATCH($C15,Prices_MTM!$A:$A,0))-INDEX(Prices_MTM!B:B,MATCH($B15,Prices_MTM!$A:$A,0))) -> -0.57461788 | F15: % | G15: =IF(F15="%",INDEX(Prices_MTM!C:C,MATCH($C15,Prices_MTM!$A:$A,0))/INDEX(Prices_MTM!C:C,MATCH($B15,Prices_MTM!$A:$A,0))-1,INDEX(Prices_MTM!C:C,MATCH($C15,Prices_MTM!$A:$A,0))-INDEX(Prices_MTM!C:C,MATCH($B15,Prices_MTM!$A:$A,0))) -> -0.60602357 | H15: =IF(D15="%",$B$4*(1+E15),IF(D15="$",$B$4+E15,E15)) -> 40.904745 | I15: =IF(F15="%",$B$5*(1+G15),IF(F15="$",$B$5+G15,G15)) -> 44.897554 | J15: =Inputs!$B$5*(H15-$B$4) -> -5525525.5 | K15: =Inputs!$B$6*(I15-$B$5) -> 3453122.3 | L15: =J15+K15 -> -2072403.2 | M15: =L15/$B$6 -> -4.3664933 | N15: Multi-month shale/OPEC price war.
A16: Parallel crash -30% | D16: % | E16: -0.3 | F16: % | G16: -0.3 | H16: =IF(D16="%",$B$4*(1+E16),IF(D16="$",$B$4+E16,E16)) -> 67.312 | I16: =IF(F16="%",$B$5*(1+G16),IF(F16="$",$B$5+G16,G16)) -> 79.772 | J16: =Inputs!$B$5*(H16-$B$4) -> -2884800 | K16: =Inputs!$B$6*(I16-$B$5) -> 1709400 | L16: =J16+K16 -> -1175400 | M16: =L16/$B$6 -> -2.4765336 | N16: Hypothetical.
A17: Parallel spike +30% | D17: % | E17: 0.3 | F17: % | G17: 0.3 | H17: =IF(D17="%",$B$4*(1+E17),IF(D17="$",$B$4+E17,E17)) -> 125.008 | I17: =IF(F17="%",$B$5*(1+G17),IF(F17="$",$B$5+G17,G17)) -> 148.148 | J17: =Inputs!$B$5*(H17-$B$4) -> 2884800 | K17: =Inputs!$B$6*(I17-$B$5) -> -1709400 | L17: =J17+K17 -> 1175400 | M17: =L17/$B$6 -> 2.4765336 | N17: Hypothetical.
A18: Spread blowout: WTI -$5, Brent +$10 | D18: $ | E18: -5 | F18: $ | G18: 10 | H18: =IF(D18="%",$B$4*(1+E18),IF(D18="$",$B$4+E18,E18)) -> 91.16 | I18: =IF(F18="%",$B$5*(1+G18),IF(F18="$",$B$5+G18,G18)) -> 123.96 | J18: =Inputs!$B$5*(H18-$B$4) -> -500000 | K18: =Inputs!$B$6*(I18-$B$5) -> -500000 | L18: =J18+K18 -> -1000000 | M18: =L18/$B$6 -> -2.1069709 | N18: Hypothetical Cushing glut while seaborne crude tightens.
A19: WTI to -$40 at expiry, Brent -20% | D19: level | E19: -40 | F19: % | G19: -0.2 | H19: =IF(D19="%",$B$4*(1+E19),IF(D19="$",$B$4+E19,E19)) -> -40 | I19: =IF(F19="%",$B$5*(1+G19),IF(F19="$",$B$5+G19,G19)) -> 91.168 | J19: =Inputs!$B$5*(H19-$B$4) -> -13616000 | K19: =Inputs!$B$6*(I19-$B$5) -> 1139600 | L19: =J19+K19 -> -12476400 | M19: =L19/$B$6 -> -26.287412 | N19: Hypothetical repeat of April 2020 storage squeeze.
A21: Worst scenario loss ($) | L21: =MIN(L10:L19) -> -12476400
A22: Worst scenario | L22: =INDEX(A10:A19,MATCH(L21,L10:L19,0)) -> WTI to -$40 at expiry, Brent -20%
